{"asctime": "2024-08-23 13:56:07,505", "process": 1, "levelname": "ERROR", "path": "/helloDoc/users", "method": "GET", "reason": "Error -2 connecting to redis:6379. -2.", "exc_info": "Traceback (most recent call last):\n  File \"/usr/local/lib/python3.12/site-packages/anyio/streams/memory.py\", line 105, in receive\n    return self.receive_nowait()\n           ^^^^^^^^^^^^^^^^^^^^^\n  File \"/usr/local/lib/python3.12/site-packages/anyio/streams/memory.py\", line 100, in receive_nowait\n    raise WouldBlock\nanyio.WouldBlock\n\nDuring handling of the above exception, another exception occurred:\n\nTraceback (most recent call last):\n  File \"/usr/local/lib/python3.12/site-packages/anyio/streams/memory.py\", line 118, in receive\n    return receiver.item\n           ^^^^^^^^^^^^^\nAttributeError: 'MemoryObjectItemReceiver' object has no attribute 'item'\n\nDuring handling of the above exception, another exception occurred:\n\nTraceback (most recent call last):\n  File \"/usr/local/lib/python3.12/site-packages/starlette/middleware/base.py\", line 159, in call_next\n    message = await recv_stream.receive()\n              ^^^^^^^^^^^^^^^^^^^^^^^^^^^\n  File \"/usr/local/lib/python3.12/site-packages/anyio/streams/memory.py\", line 120, in receive\n    raise EndOfStream\nanyio.EndOfStream\n\nDuring handling of the above exception, another exception occurred:\n\nTraceback (most recent call last):\n  File \"/usr/local/lib/python3.12/site-packages/logmiddleware/middleware.py\", line 125, in _execute_request\n    response: Response = await call_next(request)\n                         ^^^^^^^^^^^^^^^^^^^^^^^^\n  File \"/usr/local/lib/python3.12/site-packages/starlette/middleware/base.py\", line 165, in call_next\n    raise app_exc\n  File \"/usr/local/lib/python3.12/site-packages/starlette/middleware/base.py\", line 151, in coro\n    await self.app(scope, receive_or_disconnect, send_no_error)\n  File \"/usr/local/lib/python3.12/site-packages/starlette/middleware/exceptions.py\", line 65, in __call__\n    await wrap_app_handling_exceptions(self.app, conn)(scope, receive, send)\n  File \"/usr/local/lib/python3.12/site-packages/starlette/_exception_handler.py\", line 64, in wrapped_app\n    raise exc\n  File \"/usr/local/lib/python3.12/site-packages/starlette/_exception_handler.py\", line 53, in wrapped_app\n    await app(scope, receive, sender)\n  File \"/usr/local/lib/python3.12/site-packages/starlette/routing.py\", line 756, in __call__\n    await self.middleware_stack(scope, receive, send)\n  File \"/usr/local/lib/python3.12/site-packages/starlette/routing.py\", line 776, in app\n    await route.handle(scope, receive, send)\n  File \"/usr/local/lib/python3.12/site-packages/starlette/routing.py\", line 297, in handle\n    await self.app(scope, receive, send)\n  File \"/usr/local/lib/python3.12/site-packages/starlette/routing.py\", line 77, in app\n    await wrap_app_handling_exceptions(app, request)(scope, receive, send)\n  File \"/usr/local/lib/python3.12/site-packages/starlette/_exception_handler.py\", line 64, in wrapped_app\n    raise exc\n  File \"/usr/local/lib/python3.12/site-packages/starlette/_exception_handler.py\", line 53, in wrapped_app\n    await app(scope, receive, sender)\n  File \"/usr/local/lib/python3.12/site-packages/starlette/routing.py\", line 72, in app\n    response = await func(request)\n               ^^^^^^^^^^^^^^^^^^^\n  File \"/usr/local/lib/python3.12/site-packages/fastapi/routing.py\", line 278, in app\n    raw_response = await run_endpoint_function(\n                   ^^^^^^^^^^^^^^^^^^^^^^^^^^^^\n  File \"/usr/local/lib/python3.12/site-packages/fastapi/routing.py\", line 191, in run_endpoint_function\n    return await dependant.call(**values)\n           ^^^^^^^^^^^^^^^^^^^^^^^^^^^^^^\n  File \"/usr/local/lib/python3.12/site-packages/fastapi_cache/decorator.py\", line 127, in inner\n    ttl, ret = await backend.get_with_ttl(cache_key)\n               ^^^^^^^^^^^^^^^^^^^^^^^^^^^^^^^^^^^^^\n  File \"/usr/local/lib/python3.12/site-packages/fastapi_cache/backends/redis.py\", line 14, in get_with_ttl\n    return await (pipe.ttl(key).get(key).execute())\n           ^^^^^^^^^^^^^^^^^^^^^^^^^^^^^^^^^^^^^^^^\n  File \"/usr/local/lib/python3.12/site-packages/redis/asyncio/client.py\", line 1370, in execute\n    conn = await self.connection_pool.get_connection(\"MULTI\", self.shard_hint)\n           ^^^^^^^^^^^^^^^^^^^^^^^^^^^^^^^^^^^^^^^^^^^^^^^^^^^^^^^^^^^^^^^^^^^\n  File \"/usr/local/lib/python3.12/site-packages/redis/asyncio/connection.py\", line 1396, in get_connection\n    await connection.connect()\n  File \"/usr/local/lib/python3.12/site-packages/redis/asyncio/connection.py\", line 608, in connect\n    raise ConnectionError(self._error_message(e))\nredis.exceptions.ConnectionError: Error -2 connecting to redis:6379. -2.", "taskName": "Task-665"}

